File: 3.2 Consolidated View of Tabular Data/Data/3- Sample_Tables_CSV_Normalized/CSV_PDF/j.cej.2021.128647.csv
,Entry,Samples,Tds (°C),Td30 (°C),Tmax (°C),THRI (°C),R800 (%),Flexural Stress (MPa),Modulus (GPa),property Deflection (mm),Shore Hardness (HD),Flexural Stress (MPa)_err,Modulus (GPa)_err,property Deflection (mm)_err,Shore Hardness (HD)_err,E'(GPa),E (MPa),"Tg,DMA (°C)",Ve (mol/ dm³,HRC (J/ g.K),PHRR (W/g),Total HR (kJ/g),Peak Temp. (C),DBDBBB (g),DGEBA (g),DDS (g),Liquefied temp range (°C),Curing temperature (°C),Vectors,Ref
0,1.0,DBDBBB/ 33DDS,397.0,440.0,450.0,207.2,17.6,,,,,,,,,,,,,,,,,,,,,,"['DBDBBB', '(33)DDS']",j.cej.2021.128647
1,2.0,DBDBBB/ 44DDS,410.0,450.0,451.0,212.7,31.2,,,,,,,,,,,,,,,,,,,,,,"['DBDBBB', '(44)DDS']",j.cej.2021.128647
2,3.0,DGEBA/ 33DDS,413.0,430.0,430.0,207.4,16.5,,,,,,,,,,,,,,,,,,,,,,"['DGEBA', '(33)DDS']",j.cej.2021.128647
3,4.0,DGEBA/ 44DDS,408.0,426.0,424.0,205.2,14.8,,,,,,,,,,,,,,,,,,,,,,"['DGEBA', '(44)DDS']",j.cej.2021.128647
4,1.0,DBDBBB/ 33DDS,,,,,,80.0,3.03,4.94,77.5,12.0,0.25,1.14,0.95,,,,,,,,,7.56,-,2.48,130.0,210.0,"['DBDBBB', '(33)DDS']",j.cej.2021.128647
5,3.0,DBDBBB/ 33DDS,,,,,,,,,,,,,,1.09,7.36,120.4,0.696,268.93,266.06,18.98,467.68,7.56,-,2.48,130.0,210.0,"['DBDBBB', '(33)DDS']",j.cej.2021.128647
6,5.0,DBDBBB/ 33DDSb,,,,,,,,,,,,,,1.41,21.5,113.3,2.07,,,,,,,,,,"['DBDBBB', '(33)DDSb']",j.cej.2021.128647
7,2.0,DBDBBB/ 44DDS,,,,,,57.2,3.06,2.86,59.2,11.2,0.14,0.57,0.5,,,,,,,,,7.56,-,2.48,130.0,210.0,"['DBDBBB', '(44)DDS']",j.cej.2021.128647
8,,DBDBBB/ 44DDS,,,,,,,,,,,,,,,,,,263.32,259.3,20.93,450.18,7.56,-,2.48,130.0,210.0,"['DBDBBB', '(44)DDS']",j.cej.2021.128647
9,6.0,DBDBBB/ 44DDSb,,,,,,,,,,,,,,1.21,15.5,123.1,1.46,,,,,,,,,,"['DBDBBB', '(44)DDSb']",j.cej.2021.128647
10,4.0,DBDBBB/ 44DDSª,,,,,,,,,,,,,,1.48,6.43,134.6,0.589,,,,,,,,,,"['DBDBBB', '(44)DDSª']",j.cej.2021.128647
11,1.0,DBDBBB/33DDS,,,,,,,,,,,,,,1.08,1.94,116.1,0.185,,,,,,,,,,"['DBDBBB', '(33)DDS']",j.cej.2021.128647
12,2.0,DBDBBB/44DDS,,,,,,,,,,,,,,1.08,2.79,125.3,0.292,,,,,,,,,,"['DBDBBB', '(44)DDS']",j.cej.2021.128647
13,3.0,DGEBA/ 33DDS,,,,,,142.0,3.248,9.76,81.2,12.1,0.88,2.56,0.95,,,,,,,,,-,6.81,2.48,165.0,215.0,"['DGEBA', '(33)DDS']",j.cej.2021.128647
14,,DGEBA/ 33DDS,,,,,,,,,,,,,,,,,,421.1,414.47,24.58,435.75,-,6.81,2.48,165.0,215.0,"['DGEBA', '(33)DDS']",j.cej.2021.128647
15,4.0,DGEBA/ 44DDS,,,,,,126.3,2.856,10.52,79.7,11.9,0.24,1.48,1.5,,,,,,,,,-,6.81,2.48,165.0,215.0,"['DGEBA', '(44)DDS']",j.cej.2021.128647
16,,DGEBA/ 44DDS,,,,,,,,,,,,,,,,,,418.86,417.14,24.46,448.06,-,6.81,2.48,165.0,215.0,"['DGEBA', '(44)DDS']",j.cej.2021.128647